API: SYSTEM.storage
Time: 07:17:51 UTC 07/18/2025
Error: unable to rename (/data/.minio.sys/tmp -> /data/.minio.sys/tmp-old/d65003eb-7896-45ae-8d00-0638b8ff39de) file access denied, drive may be faulty, please investigate (*fmt.wrapError)
       7: internal/logger/logger.go:271:logger.LogIf()
       6: cmd/logging.go:156:cmd.storageLogIf()
       5: cmd/prepare-storage.go:89:cmd.bgFormatErasureCleanupTmp()
       4: cmd/xl-storage.go:272:cmd.newXLStorage()
       3: cmd/object-api-common.go:63:cmd.newStorageAPI()
       2: cmd/format-erasure.go:571:cmd.initStorageDisksWithErrors.func1()
       1: github.com/minio/pkg/v3@v3.1.3/sync/errgroup/errgroup.go:123:errgroup.(*Group).Go.func1()

API: SYSTEM.storage
Time: 07:17:51 UTC 07/18/2025
Error: unable to create (/data/.minio.sys/tmp) file access denied, drive may be faulty, please investigate (*fmt.wrapError)
       7: internal/logger/logger.go:271:logger.LogIf()
       6: cmd/logging.go:156:cmd.storageLogIf()
       5: cmd/prepare-storage.go:96:cmd.bgFormatErasureCleanupTmp()
       4: cmd/xl-storage.go:272:cmd.newXLStorage()
       3: cmd/object-api-common.go:63:cmd.newStorageAPI()
       2: cmd/format-erasure.go:571:cmd.initStorageDisksWithErrors.func1()
       1: github.com/minio/pkg/v3@v3.1.3/sync/errgroup/errgroup.go:123:errgroup.(*Group).Go.func1()
FATAL Unable to initialize backend: file access denied
mc: <ERROR> Unable to initialize new alias from the provided credentials. Get "http://localhost:9000/probe-bsign-nlhie2naa0hbcls3xeia9jyo9x5n9r/?location=": dial tcp [::1]:9000: connect: connection refused.
mc: <ERROR> Unable to initialize admin connection. No valid configuration found for 'myminio/' host alias.
Bucket created successfully `myminio/dummy`.
Bucket created successfully `myminio/datalake`.
Bucket created successfully `myminio/datalakehouse`.
Bucket created successfully `myminio/warehouse`.
mc: <ERROR> Unable to prepare URL for copying. Unable to guess the type of copy operation.

----------------------------------------------------------

[2025-07-18 07:17:56 +0000] [7] [INFO] Starting gunicorn 22.0.0
[2025-07-18 07:17:56 +0000] [7] [INFO] Listening at: http://0.0.0.0:8088 (7)
[2025-07-18 07:17:56 +0000] [7] [INFO] Using worker: gthread
[2025-07-18 07:17:56 +0000] [8] [INFO] Booting worker with pid: 8
/app/superset/config.py:42: UserWarning: pkg_resources is deprecated as an API. See https://setuptools.pypa.io/en/latest/pkg_resources.html. The pkg_resources package is slated for removal as early as 2025-11-30. Refrain from using this package or pin to Setuptools<81.
  import pkg_resources
Loaded your LOCAL configuration at [/app/superset_config.py]
/usr/local/lib/python3.10/site-packages/flask_limiter/extension.py:333: UserWarning: Using the in-memory storage for tracking rate limits as no storage was explicitly specified. This is not recommended for production use. See: https://flask-limiter.readthedocs.io#configuring-a-storage-backend for documentation about configuring the storage backend.
  warnings.warn(
2025-07-18 07:18:00,974:INFO:superset.utils.screenshots:No PIL installation found
2025-07-18 07:18:01,981:INFO:superset.utils.pdf:No PIL installation found
127.0.0.1 - - [18/Jul/2025:07:18:26 +0000] "GET /health HTTP/1.1" 200 2 "-" "curl/7.88.1"
127.0.0.1 - - [18/Jul/2025:07:18:56 +0000] "GET /health HTTP/1.1" 200 2 "-" "curl/7.88.1"
127.0.0.1 - - [18/Jul/2025:07:19:26 +0000] "GET /health HTTP/1.1" 200 2 "-" "curl/7.88.1"
127.0.0.1 - - [18/Jul/2025:07:19:57 +0000] "GET /health HTTP/1.1" 200 2 "-" "curl/7.88.1"
127.0.0.1 - - [18/Jul/2025:07:20:27 +0000] "GET /health HTTP/1.1" 200 2 "-" "curl/7.88.1"
127.0.0.1 - - [18/Jul/2025:07:20:57 +0000] "GET /health HTTP/1.1" 200 2 "-" "curl/7.88.1"
127.0.0.1 - - [18/Jul/2025:07:21:27 +0000] "GET /health HTTP/1.1" 200 2 "-" "curl/7.88.1"
127.0.0.1 - - [18/Jul/2025:07:21:57 +0000] "GET /health HTTP/1.1" 200 2 "-" "curl/7.88.1"
127.0.0.1 - - [18/Jul/2025:07:22:27 +0000] "GET /health HTTP/1.1" 200 2 "-" "curl/7.88.1"
127.0.0.1 - - [18/Jul/2025:07:22:57 +0000] "GET /health HTTP/1.1" 200 2 "-" "curl/7.88.1"
192.168.1.10 - - [18/Jul/2025:07:23:20 +0000] "GET / HTTP/1.1" 302 223 "-" "Mozilla/5.0 (Windows NT 10.0; Win64; x64) AppleWebKit/537.36 (KHTML, like Gecko) Chrome/138.0.0.0 Safari/537.36"
2025-07-18 07:23:20,150:WARNING:root:Class 'werkzeug.local.LocalProxy' is not mapped
2025-07-18 07:23:20,159:ERROR:root:DBEventLogger failed to log event(s)
2025-07-18 07:23:20,159:ERROR:root:(sqlite3.OperationalError) no such table: logs
[SQL: INSERT INTO logs (action, json, dttm, duration_ms) VALUES (?, ?, ?, ?)]
[parameters: ('welcome', '{"path": "/superset/welcome/", "object_ref": "Superset.welcome"}', '2025-07-18 07:23:20.158225', 0)]
(Background on this error at: https://sqlalche.me/e/14/e3q8)
Traceback (most recent call last):
  File "/usr/local/lib/python3.10/site-packages/sqlalchemy/engine/base.py", line 1910, in _execute_context
    self.dialect.do_execute(
  File "/usr/local/lib/python3.10/site-packages/sqlalchemy/engine/default.py", line 736, in do_execute
    cursor.execute(statement, parameters)
sqlite3.OperationalError: no such table: logs

The above exception was the direct cause of the following exception:

Traceback (most recent call last):
  File "/app/superset/utils/log.py", line 405, in log
    db.session.bulk_save_objects(logs)
  File "<string>", line 2, in bulk_save_objects
  File "/usr/local/lib/python3.10/site-packages/sqlalchemy/orm/session.py", line 3705, in bulk_save_objects
    self._bulk_save_mappings(
  File "/usr/local/lib/python3.10/site-packages/sqlalchemy/orm/session.py", line 3912, in _bulk_save_mappings
    with util.safe_reraise():
  File "/usr/local/lib/python3.10/site-packages/sqlalchemy/util/langhelpers.py", line 70, in __exit__
    compat.raise_(
  File "/usr/local/lib/python3.10/site-packages/sqlalchemy/util/compat.py", line 211, in raise_
    raise exception
  File "/usr/local/lib/python3.10/site-packages/sqlalchemy/orm/session.py", line 3901, in _bulk_save_mappings
    persistence._bulk_insert(
  File "/usr/local/lib/python3.10/site-packages/sqlalchemy/orm/persistence.py", line 107, in _bulk_insert
    _emit_insert_statements(
  File "/usr/local/lib/python3.10/site-packages/sqlalchemy/orm/persistence.py", line 1097, in _emit_insert_statements
    c = connection._execute_20(
  File "/usr/local/lib/python3.10/site-packages/sqlalchemy/engine/base.py", line 1710, in _execute_20
    return meth(self, args_10style, kwargs_10style, execution_options)
  File "/usr/local/lib/python3.10/site-packages/sqlalchemy/sql/elements.py", line 334, in _execute_on_connection
    return connection._execute_clauseelement(
  File "/usr/local/lib/python3.10/site-packages/sqlalchemy/engine/base.py", line 1577, in _execute_clauseelement
    ret = self._execute_context(
  File "/usr/local/lib/python3.10/site-packages/sqlalchemy/engine/base.py", line 1953, in _execute_context
    self._handle_dbapi_exception(
  File "/usr/local/lib/python3.10/site-packages/sqlalchemy/engine/base.py", line 2134, in _handle_dbapi_exception
    util.raise_(
  File "/usr/local/lib/python3.10/site-packages/sqlalchemy/util/compat.py", line 211, in raise_
    raise exception
  File "/usr/local/lib/python3.10/site-packages/sqlalchemy/engine/base.py", line 1910, in _execute_context
    self.dialect.do_execute(
  File "/usr/local/lib/python3.10/site-packages/sqlalchemy/engine/default.py", line 736, in do_execute
    cursor.execute(statement, parameters)
sqlalchemy.exc.OperationalError: (sqlite3.OperationalError) no such table: logs
[SQL: INSERT INTO logs (action, json, dttm, duration_ms) VALUES (?, ?, ?, ?)]
[parameters: ('welcome', '{"path": "/superset/welcome/", "object_ref": "Superset.welcome"}', '2025-07-18 07:23:20.158225', 0)]
(Background on this error at: https://sqlalche.me/e/14/e3q8)
192.168.1.10 - - [18/Jul/2025:07:23:20 +0000] "GET /superset/welcome/ HTTP/1.1" 302 201 "-" "Mozilla/5.0 (Windows NT 10.0; Win64; x64) AppleWebKit/537.36 (KHTML, like Gecko) Chrome/138.0.0.0 Safari/537.36"
192.168.1.10 - - [18/Jul/2025:07:23:20 +0000] "GET /login/ HTTP/1.1" 200 4002 "-" "Mozilla/5.0 (Windows NT 10.0; Win64; x64) AppleWebKit/537.36 (KHTML, like Gecko) Chrome/138.0.0.0 Safari/537.36"
192.168.1.10 - - [18/Jul/2025:07:23:20 +0000] "GET /static/appbuilder/css/bootstrap.min.css HTTP/1.1" 200 19736 "http://192.168.1.111:8088/login/" "Mozilla/5.0 (Windows NT 10.0; Win64; x64) AppleWebKit/537.36 (KHTML, like Gecko) Chrome/138.0.0.0 Safari/537.36"
192.168.1.10 - - [18/Jul/2025:07:23:20 +0000] "GET /static/appbuilder/css/fontawesome/regular.min.css HTTP/1.1" 200 327 "http://192.168.1.111:8088/login/" "Mozilla/5.0 (Windows NT 10.0; Win64; x64) AppleWebKit/537.36 (KHTML, like Gecko) Chrome/138.0.0.0 Safari/537.36"
192.168.1.10 - - [18/Jul/2025:07:23:20 +0000] "GET /static/appbuilder/css/fontawesome/solid.min.css HTTP/1.1" 200 325 "http://192.168.1.111:8088/login/" "Mozilla/5.0 (Windows NT 10.0; Win64; x64) AppleWebKit/537.36 (KHTML, like Gecko) Chrome/138.0.0.0 Safari/537.36"
192.168.1.10 - - [18/Jul/2025:07:23:20 +0000] "GET /static/appbuilder/css/bootstrap-datepicker/bootstrap-datepicker3.min.css HTTP/1.1" 200 2391 "http://192.168.1.111:8088/login/" "Mozilla/5.0 (Windows NT 10.0; Win64; x64) AppleWebKit/537.36 (KHTML, like Gecko) Chrome/138.0.0.0 Safari/537.36"
192.168.1.10 - - [18/Jul/2025:07:23:20 +0000] "GET /static/appbuilder/css/fontawesome/fontawesome.min.css HTTP/1.1" 200 17395 "http://192.168.1.111:8088/login/" "Mozilla/5.0 (Windows NT 10.0; Win64; x64) AppleWebKit/537.36 (KHTML, like Gecko) Chrome/138.0.0.0 Safari/537.36"
192.168.1.10 - - [18/Jul/2025:07:23:20 +0000] "GET /static/appbuilder/css/fontawesome/brands.min.css HTTP/1.1" 200 4724 "http://192.168.1.111:8088/login/" "Mozilla/5.0 (Windows NT 10.0; Win64; x64) AppleWebKit/537.36 (KHTML, like Gecko) Chrome/138.0.0.0 Safari/537.36"
192.168.1.10 - - [18/Jul/2025:07:23:20 +0000] "GET /static/appbuilder/css/fontawesome/v4-shims.min.css HTTP/1.1" 200 4352 "http://192.168.1.111:8088/login/" "Mozilla/5.0 (Windows NT 10.0; Win64; x64) AppleWebKit/537.36 (KHTML, like Gecko) Chrome/138.0.0.0 Safari/537.36"
192.168.1.10 - - [18/Jul/2025:07:23:20 +0000] "GET /static/appbuilder/css/select2/select2-bootstrap.min.css HTTP/1.1" 200 2338 "http://192.168.1.111:8088/login/" "Mozilla/5.0 (Windows NT 10.0; Win64; x64) AppleWebKit/537.36 (KHTML, like Gecko) Chrome/138.0.0.0 Safari/537.36"
192.168.1.10 - - [18/Jul/2025:07:23:20 +0000] "GET /static/appbuilder/css/flags/flags16.css HTTP/1.1" 200 1744 "http://192.168.1.111:8088/login/" "Mozilla/5.0 (Windows NT 10.0; Win64; x64) AppleWebKit/537.36 (KHTML, like Gecko) Chrome/138.0.0.0 Safari/537.36"
192.168.1.10 - - [18/Jul/2025:07:23:20 +0000] "GET /static/appbuilder/css/select2/select2.min.css HTTP/1.1" 200 1996 "http://192.168.1.111:8088/login/" "Mozilla/5.0 (Windows NT 10.0; Win64; x64) AppleWebKit/537.36 (KHTML, like Gecko) Chrome/138.0.0.0 Safari/537.36"
192.168.1.10 - - [18/Jul/2025:07:23:20 +0000] "GET /static/appbuilder/css/ab.css HTTP/1.1" 200 330 "http://192.168.1.111:8088/login/" "Mozilla/5.0 (Windows NT 10.0; Win64; x64) AppleWebKit/537.36 (KHTML, like Gecko) Chrome/138.0.0.0 Safari/537.36"
192.168.1.10 - - [18/Jul/2025:07:23:20 +0000] "GET /static/appbuilder/js/ab_filters.js HTTP/1.1" 200 1372 "http://192.168.1.111:8088/login/" "Mozilla/5.0 (Windows NT 10.0; Win64; x64) AppleWebKit/537.36 (KHTML, like Gecko) Chrome/138.0.0.0 Safari/537.36"
192.168.1.10 - - [18/Jul/2025:07:23:20 +0000] "GET /static/appbuilder/js/ab_actions.js HTTP/1.1" 200 1106 "http://192.168.1.111:8088/login/" "Mozilla/5.0 (Windows NT 10.0; Win64; x64) AppleWebKit/537.36 (KHTML, like Gecko) Chrome/138.0.0.0 Safari/537.36"
192.168.1.10 - - [18/Jul/2025:07:23:20 +0000] "GET /static/appbuilder/js/jquery-latest.js HTTP/1.1" 200 30947 "http://192.168.1.111:8088/login/" "Mozilla/5.0 (Windows NT 10.0; Win64; x64) AppleWebKit/537.36 (KHTML, like Gecko) Chrome/138.0.0.0 Safari/537.36"
192.168.1.10 - - [18/Jul/2025:07:23:20 +0000] "GET /static/assets/images/superset-logo-horiz.png HTTP/1.1" 200 0 "http://192.168.1.111:8088/login/" "Mozilla/5.0 (Windows NT 10.0; Win64; x64) AppleWebKit/537.36 (KHTML, like Gecko) Chrome/138.0.0.0 Safari/537.36"
192.168.1.10 - - [18/Jul/2025:07:23:20 +0000] "GET /static/appbuilder/js/bootstrap.min.js HTTP/1.1" 200 10940 "http://192.168.1.111:8088/login/" "Mozilla/5.0 (Windows NT 10.0; Win64; x64) AppleWebKit/537.36 (KHTML, like Gecko) Chrome/138.0.0.0 Safari/537.36"
192.168.1.10 - - [18/Jul/2025:07:23:20 +0000] "GET /static/assets/theme.4a9120b00b1a99b8f135.entry.css HTTP/1.1" 200 85925 "http://192.168.1.111:8088/login/" "Mozilla/5.0 (Windows NT 10.0; Win64; x64) AppleWebKit/537.36 (KHTML, like Gecko) Chrome/138.0.0.0 Safari/537.36"
192.168.1.10 - - [18/Jul/2025:07:23:20 +0000] "GET /static/appbuilder/js/bootstrap-datepicker/bootstrap-datepicker.min.js HTTP/1.1" 200 10117 "http://192.168.1.111:8088/login/" "Mozilla/5.0 (Windows NT 10.0; Win64; x64) AppleWebKit/537.36 (KHTML, like Gecko) Chrome/138.0.0.0 Safari/537.36"
192.168.1.10 - - [18/Jul/2025:07:23:20 +0000] "GET /static/appbuilder/js/select2/select2.min.js HTTP/1.1" 200 19904 "http://192.168.1.111:8088/login/" "Mozilla/5.0 (Windows NT 10.0; Win64; x64) AppleWebKit/537.36 (KHTML, like Gecko) Chrome/138.0.0.0 Safari/537.36"
192.168.1.10 - - [18/Jul/2025:07:23:20 +0000] "GET /static/appbuilder/js/ab.js HTTP/1.1" 200 937 "http://192.168.1.111:8088/login/" "Mozilla/5.0 (Windows NT 10.0; Win64; x64) AppleWebKit/537.36 (KHTML, like Gecko) Chrome/138.0.0.0 Safari/537.36"
192.168.1.10 - - [18/Jul/2025:07:23:20 +0000] "GET /static/assets/theme.4a9120b00b1a99b8f135.entry.js HTTP/1.1" 200 0 "http://192.168.1.111:8088/login/" "Mozilla/5.0 (Windows NT 10.0; Win64; x64) AppleWebKit/537.36 (KHTML, like Gecko) Chrome/138.0.0.0 Safari/537.36"
192.168.1.10 - - [18/Jul/2025:07:23:20 +0000] "GET /static/assets/7802.d42c5ecca1ed29a0b772.entry.js HTTP/1.1" 200 5084 "http://192.168.1.111:8088/login/" "Mozilla/5.0 (Windows NT 10.0; Win64; x64) AppleWebKit/537.36 (KHTML, like Gecko) Chrome/138.0.0.0 Safari/537.36"
192.168.1.10 - - [18/Jul/2025:07:23:20 +0000] "GET /static/assets/preamble.ebc35ef318359a06ee90.entry.js HTTP/1.1" 200 1100 "http://192.168.1.111:8088/login/" "Mozilla/5.0 (Windows NT 10.0; Win64; x64) AppleWebKit/537.36 (KHTML, like Gecko) Chrome/138.0.0.0 Safari/537.36"
192.168.1.10 - - [18/Jul/2025:07:23:20 +0000] "GET /static/assets/8047.ef1bd484775f3c2fcfaf.entry.js HTTP/1.1" 200 20145 "http://192.168.1.111:8088/login/" "Mozilla/5.0 (Windows NT 10.0; Win64; x64) AppleWebKit/537.36 (KHTML, like Gecko) Chrome/138.0.0.0 Safari/537.36"
192.168.1.10 - - [18/Jul/2025:07:23:20 +0000] "GET /static/assets/4653.a3aae2f2b77bf43a75d7.entry.js HTTP/1.1" 200 26198 "http://192.168.1.111:8088/login/" "Mozilla/5.0 (Windows NT 10.0; Win64; x64) AppleWebKit/537.36 (KHTML, like Gecko) Chrome/138.0.0.0 Safari/537.36"
192.168.1.10 - - [18/Jul/2025:07:23:20 +0000] "GET /static/assets/8003.08638c0c9ce53450cdcd.entry.js HTTP/1.1" 200 12888 "http://192.168.1.111:8088/login/" "Mozilla/5.0 (Windows NT 10.0; Win64; x64) AppleWebKit/537.36 (KHTML, like Gecko) Chrome/138.0.0.0 Safari/537.36"
192.168.1.10 - - [18/Jul/2025:07:23:20 +0000] "GET /static/assets/menu.efe98567976debc47c2b.entry.js HTTP/1.1" 200 4854 "http://192.168.1.111:8088/login/" "Mozilla/5.0 (Windows NT 10.0; Win64; x64) AppleWebKit/537.36 (KHTML, like Gecko) Chrome/138.0.0.0 Safari/537.36"
192.168.1.10 - - [18/Jul/2025:07:23:20 +0000] "GET /static/assets/9041.12d0618bee2f06ef479d.entry.js HTTP/1.1" 200 30548 "http://192.168.1.111:8088/login/" "Mozilla/5.0 (Windows NT 10.0; Win64; x64) AppleWebKit/537.36 (KHTML, like Gecko) Chrome/138.0.0.0 Safari/537.36"
192.168.1.10 - - [18/Jul/2025:07:23:20 +0000] "GET /static/assets/7130.e2ae8c68d9701a0cf6f5.entry.js HTTP/1.1" 200 91335 "http://192.168.1.111:8088/login/" "Mozilla/5.0 (Windows NT 10.0; Win64; x64) AppleWebKit/537.36 (KHTML, like Gecko) Chrome/138.0.0.0 Safari/537.36"
192.168.1.10 - - [18/Jul/2025:07:23:20 +0000] "GET /static/assets/f1535355a7df553be385.woff2 HTTP/1.1" 200 0 "http://192.168.1.111:8088/static/assets/theme.4a9120b00b1a99b8f135.entry.css" "Mozilla/5.0 (Windows NT 10.0; Win64; x64) AppleWebKit/537.36 (KHTML, like Gecko) Chrome/138.0.0.0 Safari/537.36"
192.168.1.10 - - [18/Jul/2025:07:23:20 +0000] "GET /static/appbuilder/css/webfonts/fa-solid-900.woff2 HTTP/1.1" 200 0 "http://192.168.1.111:8088/static/appbuilder/css/fontawesome/solid.min.css" "Mozilla/5.0 (Windows NT 10.0; Win64; x64) AppleWebKit/537.36 (KHTML, like Gecko) Chrome/138.0.0.0 Safari/537.36"
192.168.1.10 - - [18/Jul/2025:07:23:20 +0000] "GET /static/assets/1190.bdfed9a3ee969ce61e6e.entry.js HTTP/1.1" 200 381754 "http://192.168.1.111:8088/login/" "Mozilla/5.0 (Windows NT 10.0; Win64; x64) AppleWebKit/537.36 (KHTML, like Gecko) Chrome/138.0.0.0 Safari/537.36"
192.168.1.10 - - [18/Jul/2025:07:23:20 +0000] "GET /static/assets/vendors.fa5a4f129e562726a1c5.entry.js HTTP/1.1" 200 1011237 "http://192.168.1.111:8088/login/" "Mozilla/5.0 (Windows NT 10.0; Win64; x64) AppleWebKit/537.36 (KHTML, like Gecko) Chrome/138.0.0.0 Safari/537.36"
192.168.1.10 - - [18/Jul/2025:07:23:21 +0000] "GET /static/assets/2dc0f855b47deb513745.chunk.js HTTP/1.1" 200 514 "http://192.168.1.111:8088/login/" "Mozilla/5.0 (Windows NT 10.0; Win64; x64) AppleWebKit/537.36 (KHTML, like Gecko) Chrome/138.0.0.0 Safari/537.36"
192.168.1.10 - - [18/Jul/2025:07:23:21 +0000] "GET /static/assets/images/favicon.png HTTP/1.1" 200 0 "http://192.168.1.111:8088/login/" "Mozilla/5.0 (Windows NT 10.0; Win64; x64) AppleWebKit/537.36 (KHTML, like Gecko) Chrome/138.0.0.0 Safari/537.36"
127.0.0.1 - - [18/Jul/2025:07:23:27 +0000] "GET /health HTTP/1.1" 200 2 "-" "curl/7.88.1"
192.168.1.10 - - [18/Jul/2025:07:23:28 +0000] "POST /login/ HTTP/1.1" 302 215 "http://192.168.1.111:8088/login/" "Mozilla/5.0 (Windows NT 10.0; Win64; x64) AppleWebKit/537.36 (KHTML, like Gecko) Chrome/138.0.0.0 Safari/537.36"
192.168.1.10 - - [18/Jul/2025:07:23:28 +0000] "GET /login/?next=/ HTTP/1.1" 200 4081 "http://192.168.1.111:8088/login/" "Mozilla/5.0 (Windows NT 10.0; Win64; x64) AppleWebKit/537.36 (KHTML, like Gecko) Chrome/138.0.0.0 Safari/537.36"
192.168.1.10 - - [18/Jul/2025:07:23:28 +0000] "GET /static/assets/5d2eaa33f8194c062cad.woff2 HTTP/1.1" 200 0 "http://192.168.1.111:8088/static/assets/theme.4a9120b00b1a99b8f135.entry.css" "Mozilla/5.0 (Windows NT 10.0; Win64; x64) AppleWebKit/537.36 (KHTML, like Gecko) Chrome/138.0.0.0 Safari/537.36"
127.0.0.1 - - [18/Jul/2025:07:23:57 +0000] "GET /health HTTP/1.1" 200 2 "-" "curl/7.88.1"
192.168.1.10 - - [18/Jul/2025:07:23:59 +0000] "POST /login/?next=/ HTTP/1.1" 302 215 "http://192.168.1.111:8088/login/?next=/" "Mozilla/5.0 (Windows NT 10.0; Win64; x64) AppleWebKit/537.36 (KHTML, like Gecko) Chrome/138.0.0.0 Safari/537.36"
192.168.1.10 - - [18/Jul/2025:07:23:59 +0000] "GET /login/?next=/ HTTP/1.1" 200 4081 "http://192.168.1.111:8088/login/?next=/" "Mozilla/5.0 (Windows NT 10.0; Win64; x64) AppleWebKit/537.36 (KHTML, like Gecko) Chrome/138.0.0.0 Safari/537.36"
192.168.1.10 - - [18/Jul/2025:07:24:06 +0000] "POST /login/?next=/ HTTP/1.1" 302 215 "http://192.168.1.111:8088/login/?next=/" "Mozilla/5.0 (Windows NT 10.0; Win64; x64) AppleWebKit/537.36 (KHTML, like Gecko) Chrome/138.0.0.0 Safari/537.36"
192.168.1.10 - - [18/Jul/2025:07:24:06 +0000] "GET /login/?next=/ HTTP/1.1" 200 4083 "http://192.168.1.111:8088/login/?next=/" "Mozilla/5.0 (Windows NT 10.0; Win64; x64) AppleWebKit/537.36 (KHTML, like Gecko) Chrome/138.0.0.0 Safari/537.36"
127.0.0.1 - - [18/Jul/2025:07:24:28 +0000] "GET /health HTTP/1.1" 200 2 "-" "curl/7.88.1"
127.0.0.1 - - [18/Jul/2025:07:24:58 +0000] "GET /health HTTP/1.1" 200 2 "-" "curl/7.88.1"
127.0.0.1 - - [18/Jul/2025:07:25:28 +0000] "GET /health HTTP/1.1" 200 2 "-" "curl/7.88.1"
127.0.0.1 - - [18/Jul/2025:07:25:58 +0000] "GET /health HTTP/1.1" 200 2 "-" "curl/7.88.1"
127.0.0.1 - - [18/Jul/2025:07:26:28 +0000] "GET /health HTTP/1.1" 200 2 "-" "curl/7.88.1"
127.0.0.1 - - [18/Jul/2025:07:26:58 +0000] "GET /health HTTP/1.1" 200 2 "-" "curl/7.88.1"
127.0.0.1 - - [18/Jul/2025:07:27:28 +0000] "GET /health HTTP/1.1" 200 2 "-" "curl/7.88.1"
127.0.0.1 - - [18/Jul/2025:07:27:58 +0000] "GET /health HTTP/1.1" 200 2 "-" "curl/7.88.1"
192.168.1.10 - - [18/Jul/2025:07:28:08 +0000] "GET /login/?next=/ HTTP/1.1" 200 4002 "-" "Mozilla/5.0 (Windows NT 10.0; Win64; x64) AppleWebKit/537.36 (KHTML, like Gecko) Chrome/138.0.0.0 Safari/537.36"
192.168.1.10 - - [18/Jul/2025:07:28:15 +0000] "POST /login/?next=/ HTTP/1.1" 302 215 "http://192.168.1.111:8088/login/?next=/" "Mozilla/5.0 (Windows NT 10.0; Win64; x64) AppleWebKit/537.36 (KHTML, like Gecko) Chrome/138.0.0.0 Safari/537.36"
192.168.1.10 - - [18/Jul/2025:07:28:15 +0000] "GET /login/?next=/ HTTP/1.1" 200 4080 "http://192.168.1.111:8088/login/?next=/" "Mozilla/5.0 (Windows NT 10.0; Win64; x64) AppleWebKit/537.36 (KHTML, like Gecko) Chrome/138.0.0.0 Safari/537.36"
127.0.0.1 - - [18/Jul/2025:07:28:28 +0000] "GET /health HTTP/1.1" 200 2 "-" "curl/7.88.1"
127.0.0.1 - - [18/Jul/2025:07:28:58 +0000] "GET /health HTTP/1.1" 200 2 "-" "curl/7.88.1"
127.0.0.1 - - [18/Jul/2025:07:29:29 +0000] "GET /health HTTP/1.1" 200 2 "-" "curl/7.88.1"
192.168.1.10 - - [18/Jul/2025:07:29:45 +0000] "GET /login/?next=/ HTTP/1.1" 200 4002 "-" "Mozilla/5.0 (Windows NT 10.0; Win64; x64) AppleWebKit/537.36 (KHTML, like Gecko) Chrome/138.0.0.0 Safari/537.36"
192.168.1.10 - - [18/Jul/2025:07:29:50 +0000] "POST /login/?next=/ HTTP/1.1" 302 189 "http://192.168.1.111:8088/login/?next=/" "Mozilla/5.0 (Windows NT 10.0; Win64; x64) AppleWebKit/537.36 (KHTML, like Gecko) Chrome/138.0.0.0 Safari/537.36"
192.168.1.10 - - [18/Jul/2025:07:29:50 +0000] "GET / HTTP/1.1" 302 223 "http://192.168.1.111:8088/login/?next=/" "Mozilla/5.0 (Windows NT 10.0; Win64; x64) AppleWebKit/537.36 (KHTML, like Gecko) Chrome/138.0.0.0 Safari/537.36"
2025-07-18 07:29:50,923:WARNING:superset.views.error_handling:Exception
Traceback (most recent call last):
  File "/usr/local/lib/python3.10/site-packages/sqlalchemy/engine/base.py", line 1910, in _execute_context
    self.dialect.do_execute(
  File "/usr/local/lib/python3.10/site-packages/sqlalchemy/engine/default.py", line 736, in do_execute
    cursor.execute(statement, parameters)
sqlite3.OperationalError: no such table: user_attribute

The above exception was the direct cause of the following exception:

Traceback (most recent call last):
  File "/usr/local/lib/python3.10/site-packages/flask/app.py", line 1484, in full_dispatch_request
    rv = self.dispatch_request()
  File "/usr/local/lib/python3.10/site-packages/flask/app.py", line 1469, in dispatch_request
    return self.ensure_sync(self.view_functions[rule.endpoint])(**view_args)
  File "/app/superset/utils/log.py", line 303, in wrapper
    value = f(*args, **kwargs)
  File "/app/superset/views/core.py", line 902, in welcome
    .scalar()
  File "/usr/local/lib/python3.10/site-packages/sqlalchemy/orm/query.py", line 2893, in scalar
    ret = self.one()
  File "/usr/local/lib/python3.10/site-packages/sqlalchemy/orm/query.py", line 2870, in one
    return self._iter().one()
  File "/usr/local/lib/python3.10/site-packages/sqlalchemy/orm/query.py", line 2916, in _iter
    result = self.session.execute(
  File "/usr/local/lib/python3.10/site-packages/sqlalchemy/orm/session.py", line 1717, in execute
    result = conn._execute_20(statement, params or {}, execution_options)
  File "/usr/local/lib/python3.10/site-packages/sqlalchemy/engine/base.py", line 1710, in _execute_20
    return meth(self, args_10style, kwargs_10style, execution_options)
  File "/usr/local/lib/python3.10/site-packages/sqlalchemy/sql/elements.py", line 334, in _execute_on_connection
    return connection._execute_clauseelement(
  File "/usr/local/lib/python3.10/site-packages/sqlalchemy/engine/base.py", line 1577, in _execute_clauseelement
    ret = self._execute_context(
  File "/usr/local/lib/python3.10/site-packages/sqlalchemy/engine/base.py", line 1953, in _execute_context
    self._handle_dbapi_exception(
  File "/usr/local/lib/python3.10/site-packages/sqlalchemy/engine/base.py", line 2134, in _handle_dbapi_exception
    util.raise_(
  File "/usr/local/lib/python3.10/site-packages/sqlalchemy/util/compat.py", line 211, in raise_
    raise exception
  File "/usr/local/lib/python3.10/site-packages/sqlalchemy/engine/base.py", line 1910, in _execute_context
    self.dialect.do_execute(
  File "/usr/local/lib/python3.10/site-packages/sqlalchemy/engine/default.py", line 736, in do_execute
    cursor.execute(statement, parameters)
sqlalchemy.exc.OperationalError: (sqlite3.OperationalError) no such table: user_attribute
[SQL: SELECT user_attribute.welcome_dashboard_id AS user_attribute_welcome_dashboard_id 
FROM user_attribute 
WHERE user_attribute.user_id = ?]
[parameters: (1,)]
(Background on this error at: https://sqlalche.me/e/14/e3q8)
2025-07-18 07:29:50,926:ERROR:superset.views.error_handling:(sqlite3.OperationalError) no such table: user_attribute
[SQL: SELECT user_attribute.welcome_dashboard_id AS user_attribute_welcome_dashboard_id 
FROM user_attribute 
WHERE user_attribute.user_id = ?]
[parameters: (1,)]
(Background on this error at: https://sqlalche.me/e/14/e3q8)
Traceback (most recent call last):
  File "/usr/local/lib/python3.10/site-packages/sqlalchemy/engine/base.py", line 1910, in _execute_context
    self.dialect.do_execute(
  File "/usr/local/lib/python3.10/site-packages/sqlalchemy/engine/default.py", line 736, in do_execute
    cursor.execute(statement, parameters)
sqlite3.OperationalError: no such table: user_attribute

The above exception was the direct cause of the following exception:

Traceback (most recent call last):
  File "/usr/local/lib/python3.10/site-packages/flask/app.py", line 1484, in full_dispatch_request
    rv = self.dispatch_request()
  File "/usr/local/lib/python3.10/site-packages/flask/app.py", line 1469, in dispatch_request
    return self.ensure_sync(self.view_functions[rule.endpoint])(**view_args)
  File "/app/superset/utils/log.py", line 303, in wrapper
    value = f(*args, **kwargs)
  File "/app/superset/views/core.py", line 902, in welcome
    .scalar()
  File "/usr/local/lib/python3.10/site-packages/sqlalchemy/orm/query.py", line 2893, in scalar
    ret = self.one()
  File "/usr/local/lib/python3.10/site-packages/sqlalchemy/orm/query.py", line 2870, in one
    return self._iter().one()
  File "/usr/local/lib/python3.10/site-packages/sqlalchemy/orm/query.py", line 2916, in _iter
    result = self.session.execute(
  File "/usr/local/lib/python3.10/site-packages/sqlalchemy/orm/session.py", line 1717, in execute
    result = conn._execute_20(statement, params or {}, execution_options)
  File "/usr/local/lib/python3.10/site-packages/sqlalchemy/engine/base.py", line 1710, in _execute_20
    return meth(self, args_10style, kwargs_10style, execution_options)
  File "/usr/local/lib/python3.10/site-packages/sqlalchemy/sql/elements.py", line 334, in _execute_on_connection
    return connection._execute_clauseelement(
  File "/usr/local/lib/python3.10/site-packages/sqlalchemy/engine/base.py", line 1577, in _execute_clauseelement
    ret = self._execute_context(
  File "/usr/local/lib/python3.10/site-packages/sqlalchemy/engine/base.py", line 1953, in _execute_context
    self._handle_dbapi_exception(
  File "/usr/local/lib/python3.10/site-packages/sqlalchemy/engine/base.py", line 2134, in _handle_dbapi_exception
    util.raise_(
  File "/usr/local/lib/python3.10/site-packages/sqlalchemy/util/compat.py", line 211, in raise_
    raise exception
  File "/usr/local/lib/python3.10/site-packages/sqlalchemy/engine/base.py", line 1910, in _execute_context
    self.dialect.do_execute(
  File "/usr/local/lib/python3.10/site-packages/sqlalchemy/engine/default.py", line 736, in do_execute
    cursor.execute(statement, parameters)
sqlalchemy.exc.OperationalError: (sqlite3.OperationalError) no such table: user_attribute
[SQL: SELECT user_attribute.welcome_dashboard_id AS user_attribute_welcome_dashboard_id 
FROM user_attribute 
WHERE user_attribute.user_id = ?]
[parameters: (1,)]
(Background on this error at: https://sqlalche.me/e/14/e3q8)
192.168.1.10 - - [18/Jul/2025:07:29:50 +0000] "GET /superset/welcome/ HTTP/1.1" 500 0 "http://192.168.1.111:8088/login/?next=/" "Mozilla/5.0 (Windows NT 10.0; Win64; x64) AppleWebKit/537.36 (KHTML, like Gecko) Chrome/138.0.0.0 Safari/537.36"
192.168.1.10 - - [18/Jul/2025:07:29:50 +0000] "GET /static/assets/b01fb73b111d937e4c09.png HTTP/1.1" 200 0 "http://192.168.1.111:8088/superset/welcome/" "Mozilla/5.0 (Windows NT 10.0; Win64; x64) AppleWebKit/537.36 (KHTML, like Gecko) Chrome/138.0.0.0 Safari/537.36"
192.168.1.10 - - [18/Jul/2025:07:29:51 +0000] "GET /static/assets/e3bafb62eb2592c0bb0e.png HTTP/1.1" 200 0 "http://192.168.1.111:8088/superset/welcome/" "Mozilla/5.0 (Windows NT 10.0; Win64; x64) AppleWebKit/537.36 (KHTML, like Gecko) Chrome/138.0.0.0 Safari/537.36"
2025-07-18 07:29:58,654:WARNING:superset.views.error_handling:Exception
Traceback (most recent call last):
  File "/usr/local/lib/python3.10/site-packages/sqlalchemy/engine/base.py", line 1910, in _execute_context
    self.dialect.do_execute(
  File "/usr/local/lib/python3.10/site-packages/sqlalchemy/engine/default.py", line 736, in do_execute
    cursor.execute(statement, parameters)
sqlite3.OperationalError: no such table: user_attribute

The above exception was the direct cause of the following exception:

Traceback (most recent call last):
  File "/usr/local/lib/python3.10/site-packages/flask/app.py", line 1484, in full_dispatch_request
    rv = self.dispatch_request()
  File "/usr/local/lib/python3.10/site-packages/flask/app.py", line 1469, in dispatch_request
    return self.ensure_sync(self.view_functions[rule.endpoint])(**view_args)
  File "/app/superset/utils/log.py", line 303, in wrapper
    value = f(*args, **kwargs)
  File "/app/superset/views/core.py", line 902, in welcome
    .scalar()
  File "/usr/local/lib/python3.10/site-packages/sqlalchemy/orm/query.py", line 2893, in scalar
    ret = self.one()
  File "/usr/local/lib/python3.10/site-packages/sqlalchemy/orm/query.py", line 2870, in one
    return self._iter().one()
  File "/usr/local/lib/python3.10/site-packages/sqlalchemy/orm/query.py", line 2916, in _iter
    result = self.session.execute(
  File "/usr/local/lib/python3.10/site-packages/sqlalchemy/orm/session.py", line 1717, in execute
    result = conn._execute_20(statement, params or {}, execution_options)
  File "/usr/local/lib/python3.10/site-packages/sqlalchemy/engine/base.py", line 1710, in _execute_20
    return meth(self, args_10style, kwargs_10style, execution_options)
  File "/usr/local/lib/python3.10/site-packages/sqlalchemy/sql/elements.py", line 334, in _execute_on_connection
    return connection._execute_clauseelement(
  File "/usr/local/lib/python3.10/site-packages/sqlalchemy/engine/base.py", line 1577, in _execute_clauseelement
    ret = self._execute_context(
  File "/usr/local/lib/python3.10/site-packages/sqlalchemy/engine/base.py", line 1953, in _execute_context
    self._handle_dbapi_exception(
  File "/usr/local/lib/python3.10/site-packages/sqlalchemy/engine/base.py", line 2134, in _handle_dbapi_exception
    util.raise_(
  File "/usr/local/lib/python3.10/site-packages/sqlalchemy/util/compat.py", line 211, in raise_
    raise exception
  File "/usr/local/lib/python3.10/site-packages/sqlalchemy/engine/base.py", line 1910, in _execute_context
    self.dialect.do_execute(
  File "/usr/local/lib/python3.10/site-packages/sqlalchemy/engine/default.py", line 736, in do_execute
    cursor.execute(statement, parameters)
sqlalchemy.exc.OperationalError: (sqlite3.OperationalError) no such table: user_attribute
[SQL: SELECT user_attribute.welcome_dashboard_id AS user_attribute_welcome_dashboard_id 
FROM user_attribute 
WHERE user_attribute.user_id = ?]
[parameters: (1,)]
(Background on this error at: https://sqlalche.me/e/14/e3q8)
2025-07-18 07:29:58,655:ERROR:superset.views.error_handling:(sqlite3.OperationalError) no such table: user_attribute
[SQL: SELECT user_attribute.welcome_dashboard_id AS user_attribute_welcome_dashboard_id 
FROM user_attribute 
WHERE user_attribute.user_id = ?]
[parameters: (1,)]
(Background on this error at: https://sqlalche.me/e/14/e3q8)
Traceback (most recent call last):
  File "/usr/local/lib/python3.10/site-packages/sqlalchemy/engine/base.py", line 1910, in _execute_context
    self.dialect.do_execute(
  File "/usr/local/lib/python3.10/site-packages/sqlalchemy/engine/default.py", line 736, in do_execute
    cursor.execute(statement, parameters)
sqlite3.OperationalError: no such table: user_attribute

The above exception was the direct cause of the following exception:

Traceback (most recent call last):
  File "/usr/local/lib/python3.10/site-packages/flask/app.py", line 1484, in full_dispatch_request
    rv = self.dispatch_request()
  File "/usr/local/lib/python3.10/site-packages/flask/app.py", line 1469, in dispatch_request
    return self.ensure_sync(self.view_functions[rule.endpoint])(**view_args)
  File "/app/superset/utils/log.py", line 303, in wrapper
    value = f(*args, **kwargs)
  File "/app/superset/views/core.py", line 902, in welcome
    .scalar()
  File "/usr/local/lib/python3.10/site-packages/sqlalchemy/orm/query.py", line 2893, in scalar
    ret = self.one()
  File "/usr/local/lib/python3.10/site-packages/sqlalchemy/orm/query.py", line 2870, in one
    return self._iter().one()
  File "/usr/local/lib/python3.10/site-packages/sqlalchemy/orm/query.py", line 2916, in _iter
    result = self.session.execute(
  File "/usr/local/lib/python3.10/site-packages/sqlalchemy/orm/session.py", line 1717, in execute
    result = conn._execute_20(statement, params or {}, execution_options)
  File "/usr/local/lib/python3.10/site-packages/sqlalchemy/engine/base.py", line 1710, in _execute_20
    return meth(self, args_10style, kwargs_10style, execution_options)
  File "/usr/local/lib/python3.10/site-packages/sqlalchemy/sql/elements.py", line 334, in _execute_on_connection
    return connection._execute_clauseelement(
  File "/usr/local/lib/python3.10/site-packages/sqlalchemy/engine/base.py", line 1577, in _execute_clauseelement
    ret = self._execute_context(
  File "/usr/local/lib/python3.10/site-packages/sqlalchemy/engine/base.py", line 1953, in _execute_context
    self._handle_dbapi_exception(
  File "/usr/local/lib/python3.10/site-packages/sqlalchemy/engine/base.py", line 2134, in _handle_dbapi_exception
    util.raise_(
  File "/usr/local/lib/python3.10/site-packages/sqlalchemy/util/compat.py", line 211, in raise_
    raise exception
  File "/usr/local/lib/python3.10/site-packages/sqlalchemy/engine/base.py", line 1910, in _execute_context
    self.dialect.do_execute(
  File "/usr/local/lib/python3.10/site-packages/sqlalchemy/engine/default.py", line 736, in do_execute
    cursor.execute(statement, parameters)
sqlalchemy.exc.OperationalError: (sqlite3.OperationalError) no such table: user_attribute
[SQL: SELECT user_attribute.welcome_dashboard_id AS user_attribute_welcome_dashboard_id 
FROM user_attribute 
WHERE user_attribute.user_id = ?]
[parameters: (1,)]
(Background on this error at: https://sqlalche.me/e/14/e3q8)
192.168.1.10 - - [18/Jul/2025:07:29:58 +0000] "GET /superset/welcome/ HTTP/1.1" 500 0 "http://192.168.1.111:8088/login/?next=/" "Mozilla/5.0 (Windows NT 10.0; Win64; x64) AppleWebKit/537.36 (KHTML, like Gecko) Chrome/138.0.0.0 Safari/537.36"
127.0.0.1 - - [18/Jul/2025:07:29:59 +0000] "GET /health HTTP/1.1" 200 2 "-" "curl/7.88.1"
192.168.1.10 - - [18/Jul/2025:07:29:59 +0000] "GET / HTTP/1.1" 302 223 "http://192.168.1.111:8088/superset/welcome/" "Mozilla/5.0 (Windows NT 10.0; Win64; x64) AppleWebKit/537.36 (KHTML, like Gecko) Chrome/138.0.0.0 Safari/537.36"
2025-07-18 07:29:59,691:WARNING:superset.views.error_handling:Exception
Traceback (most recent call last):
  File "/usr/local/lib/python3.10/site-packages/sqlalchemy/engine/base.py", line 1910, in _execute_context
    self.dialect.do_execute(
  File "/usr/local/lib/python3.10/site-packages/sqlalchemy/engine/default.py", line 736, in do_execute
    cursor.execute(statement, parameters)
sqlite3.OperationalError: no such table: user_attribute

The above exception was the direct cause of the following exception:

Traceback (most recent call last):
  File "/usr/local/lib/python3.10/site-packages/flask/app.py", line 1484, in full_dispatch_request
    rv = self.dispatch_request()
  File "/usr/local/lib/python3.10/site-packages/flask/app.py", line 1469, in dispatch_request
    return self.ensure_sync(self.view_functions[rule.endpoint])(**view_args)
  File "/app/superset/utils/log.py", line 303, in wrapper
    value = f(*args, **kwargs)
  File "/app/superset/views/core.py", line 902, in welcome
    .scalar()
  File "/usr/local/lib/python3.10/site-packages/sqlalchemy/orm/query.py", line 2893, in scalar
    ret = self.one()
  File "/usr/local/lib/python3.10/site-packages/sqlalchemy/orm/query.py", line 2870, in one
    return self._iter().one()
  File "/usr/local/lib/python3.10/site-packages/sqlalchemy/orm/query.py", line 2916, in _iter
    result = self.session.execute(
  File "/usr/local/lib/python3.10/site-packages/sqlalchemy/orm/session.py", line 1717, in execute
    result = conn._execute_20(statement, params or {}, execution_options)
  File "/usr/local/lib/python3.10/site-packages/sqlalchemy/engine/base.py", line 1710, in _execute_20
    return meth(self, args_10style, kwargs_10style, execution_options)
  File "/usr/local/lib/python3.10/site-packages/sqlalchemy/sql/elements.py", line 334, in _execute_on_connection
    return connection._execute_clauseelement(
  File "/usr/local/lib/python3.10/site-packages/sqlalchemy/engine/base.py", line 1577, in _execute_clauseelement
    ret = self._execute_context(
  File "/usr/local/lib/python3.10/site-packages/sqlalchemy/engine/base.py", line 1953, in _execute_context
    self._handle_dbapi_exception(
  File "/usr/local/lib/python3.10/site-packages/sqlalchemy/engine/base.py", line 2134, in _handle_dbapi_exception
    util.raise_(
  File "/usr/local/lib/python3.10/site-packages/sqlalchemy/util/compat.py", line 211, in raise_
    raise exception
  File "/usr/local/lib/python3.10/site-packages/sqlalchemy/engine/base.py", line 1910, in _execute_context
    self.dialect.do_execute(
  File "/usr/local/lib/python3.10/site-packages/sqlalchemy/engine/default.py", line 736, in do_execute
    cursor.execute(statement, parameters)
sqlalchemy.exc.OperationalError: (sqlite3.OperationalError) no such table: user_attribute
[SQL: SELECT user_attribute.welcome_dashboard_id AS user_attribute_welcome_dashboard_id 
FROM user_attribute 
WHERE user_attribute.user_id = ?]
[parameters: (1,)]
(Background on this error at: https://sqlalche.me/e/14/e3q8)
2025-07-18 07:29:59,692:ERROR:superset.views.error_handling:(sqlite3.OperationalError) no such table: user_attribute
[SQL: SELECT user_attribute.welcome_dashboard_id AS user_attribute_welcome_dashboard_id 
FROM user_attribute 
WHERE user_attribute.user_id = ?]
[parameters: (1,)]
(Background on this error at: https://sqlalche.me/e/14/e3q8)
Traceback (most recent call last):
  File "/usr/local/lib/python3.10/site-packages/sqlalchemy/engine/base.py", line 1910, in _execute_context
    self.dialect.do_execute(
  File "/usr/local/lib/python3.10/site-packages/sqlalchemy/engine/default.py", line 736, in do_execute
    cursor.execute(statement, parameters)
sqlite3.OperationalError: no such table: user_attribute

The above exception was the direct cause of the following exception:

Traceback (most recent call last):
  File "/usr/local/lib/python3.10/site-packages/flask/app.py", line 1484, in full_dispatch_request
    rv = self.dispatch_request()
  File "/usr/local/lib/python3.10/site-packages/flask/app.py", line 1469, in dispatch_request
    return self.ensure_sync(self.view_functions[rule.endpoint])(**view_args)
  File "/app/superset/utils/log.py", line 303, in wrapper
    value = f(*args, **kwargs)
  File "/app/superset/views/core.py", line 902, in welcome
    .scalar()
  File "/usr/local/lib/python3.10/site-packages/sqlalchemy/orm/query.py", line 2893, in scalar
    ret = self.one()
  File "/usr/local/lib/python3.10/site-packages/sqlalchemy/orm/query.py", line 2870, in one
    return self._iter().one()
  File "/usr/local/lib/python3.10/site-packages/sqlalchemy/orm/query.py", line 2916, in _iter
    result = self.session.execute(
  File "/usr/local/lib/python3.10/site-packages/sqlalchemy/orm/session.py", line 1717, in execute
    result = conn._execute_20(statement, params or {}, execution_options)
  File "/usr/local/lib/python3.10/site-packages/sqlalchemy/engine/base.py", line 1710, in _execute_20
    return meth(self, args_10style, kwargs_10style, execution_options)
  File "/usr/local/lib/python3.10/site-packages/sqlalchemy/sql/elements.py", line 334, in _execute_on_connection
    return connection._execute_clauseelement(
  File "/usr/local/lib/python3.10/site-packages/sqlalchemy/engine/base.py", line 1577, in _execute_clauseelement
    ret = self._execute_context(
  File "/usr/local/lib/python3.10/site-packages/sqlalchemy/engine/base.py", line 1953, in _execute_context
    self._handle_dbapi_exception(
  File "/usr/local/lib/python3.10/site-packages/sqlalchemy/engine/base.py", line 2134, in _handle_dbapi_exception
    util.raise_(
  File "/usr/local/lib/python3.10/site-packages/sqlalchemy/util/compat.py", line 211, in raise_
    raise exception
  File "/usr/local/lib/python3.10/site-packages/sqlalchemy/engine/base.py", line 1910, in _execute_context
    self.dialect.do_execute(
  File "/usr/local/lib/python3.10/site-packages/sqlalchemy/engine/default.py", line 736, in do_execute
    cursor.execute(statement, parameters)
sqlalchemy.exc.OperationalError: (sqlite3.OperationalError) no such table: user_attribute
[SQL: SELECT user_attribute.welcome_dashboard_id AS user_attribute_welcome_dashboard_id 
FROM user_attribute 
WHERE user_attribute.user_id = ?]
[parameters: (1,)]
(Background on this error at: https://sqlalche.me/e/14/e3q8)
192.168.1.10 - - [18/Jul/2025:07:29:59 +0000] "GET /superset/welcome/ HTTP/1.1" 500 0 "http://192.168.1.111:8088/superset/welcome/" "Mozilla/5.0 (Windows NT 10.0; Win64; x64) AppleWebKit/537.36 (KHTML, like Gecko) Chrome/138.0.0.0 Safari/537.36"
192.168.1.10 - - [18/Jul/2025:07:30:02 +0000] "GET / HTTP/1.1" 302 223 "http://192.168.1.111:8088/superset/welcome/" "Mozilla/5.0 (Windows NT 10.0; Win64; x64) AppleWebKit/537.36 (KHTML, like Gecko) Chrome/138.0.0.0 Safari/537.36"
2025-07-18 07:30:02,397:WARNING:superset.views.error_handling:Exception
Traceback (most recent call last):
  File "/usr/local/lib/python3.10/site-packages/sqlalchemy/engine/base.py", line 1910, in _execute_context
    self.dialect.do_execute(
  File "/usr/local/lib/python3.10/site-packages/sqlalchemy/engine/default.py", line 736, in do_execute
    cursor.execute(statement, parameters)
sqlite3.OperationalError: no such table: user_attribute

The above exception was the direct cause of the following exception:

Traceback (most recent call last):
  File "/usr/local/lib/python3.10/site-packages/flask/app.py", line 1484, in full_dispatch_request
    rv = self.dispatch_request()
  File "/usr/local/lib/python3.10/site-packages/flask/app.py", line 1469, in dispatch_request
    return self.ensure_sync(self.view_functions[rule.endpoint])(**view_args)
  File "/app/superset/utils/log.py", line 303, in wrapper
    value = f(*args, **kwargs)
  File "/app/superset/views/core.py", line 902, in welcome
    .scalar()
  File "/usr/local/lib/python3.10/site-packages/sqlalchemy/orm/query.py", line 2893, in scalar
    ret = self.one()
  File "/usr/local/lib/python3.10/site-packages/sqlalchemy/orm/query.py", line 2870, in one
    return self._iter().one()
  File "/usr/local/lib/python3.10/site-packages/sqlalchemy/orm/query.py", line 2916, in _iter
    result = self.session.execute(
  File "/usr/local/lib/python3.10/site-packages/sqlalchemy/orm/session.py", line 1717, in execute
    result = conn._execute_20(statement, params or {}, execution_options)
  File "/usr/local/lib/python3.10/site-packages/sqlalchemy/engine/base.py", line 1710, in _execute_20
    return meth(self, args_10style, kwargs_10style, execution_options)
  File "/usr/local/lib/python3.10/site-packages/sqlalchemy/sql/elements.py", line 334, in _execute_on_connection
    return connection._execute_clauseelement(
  File "/usr/local/lib/python3.10/site-packages/sqlalchemy/engine/base.py", line 1577, in _execute_clauseelement
    ret = self._execute_context(
  File "/usr/local/lib/python3.10/site-packages/sqlalchemy/engine/base.py", line 1953, in _execute_context
    self._handle_dbapi_exception(
  File "/usr/local/lib/python3.10/site-packages/sqlalchemy/engine/base.py", line 2134, in _handle_dbapi_exception
    util.raise_(
  File "/usr/local/lib/python3.10/site-packages/sqlalchemy/util/compat.py", line 211, in raise_
    raise exception
  File "/usr/local/lib/python3.10/site-packages/sqlalchemy/engine/base.py", line 1910, in _execute_context
    self.dialect.do_execute(
  File "/usr/local/lib/python3.10/site-packages/sqlalchemy/engine/default.py", line 736, in do_execute
    cursor.execute(statement, parameters)
sqlalchemy.exc.OperationalError: (sqlite3.OperationalError) no such table: user_attribute
[SQL: SELECT user_attribute.welcome_dashboard_id AS user_attribute_welcome_dashboard_id 
FROM user_attribute 
WHERE user_attribute.user_id = ?]
[parameters: (1,)]
(Background on this error at: https://sqlalche.me/e/14/e3q8)
2025-07-18 07:30:02,398:ERROR:superset.views.error_handling:(sqlite3.OperationalError) no such table: user_attribute
[SQL: SELECT user_attribute.welcome_dashboard_id AS user_attribute_welcome_dashboard_id 
FROM user_attribute 
WHERE user_attribute.user_id = ?]
[parameters: (1,)]
(Background on this error at: https://sqlalche.me/e/14/e3q8)
Traceback (most recent call last):
  File "/usr/local/lib/python3.10/site-packages/sqlalchemy/engine/base.py", line 1910, in _execute_context
    self.dialect.do_execute(
  File "/usr/local/lib/python3.10/site-packages/sqlalchemy/engine/default.py", line 736, in do_execute
    cursor.execute(statement, parameters)
sqlite3.OperationalError: no such table: user_attribute

The above exception was the direct cause of the following exception:

Traceback (most recent call last):
  File "/usr/local/lib/python3.10/site-packages/flask/app.py", line 1484, in full_dispatch_request
    rv = self.dispatch_request()
  File "/usr/local/lib/python3.10/site-packages/flask/app.py", line 1469, in dispatch_request
    return self.ensure_sync(self.view_functions[rule.endpoint])(**view_args)
  File "/app/superset/utils/log.py", line 303, in wrapper
    value = f(*args, **kwargs)
  File "/app/superset/views/core.py", line 902, in welcome
    .scalar()
  File "/usr/local/lib/python3.10/site-packages/sqlalchemy/orm/query.py", line 2893, in scalar
    ret = self.one()
  File "/usr/local/lib/python3.10/site-packages/sqlalchemy/orm/query.py", line 2870, in one
    return self._iter().one()
  File "/usr/local/lib/python3.10/site-packages/sqlalchemy/orm/query.py", line 2916, in _iter
    result = self.session.execute(
  File "/usr/local/lib/python3.10/site-packages/sqlalchemy/orm/session.py", line 1717, in execute
    result = conn._execute_20(statement, params or {}, execution_options)
  File "/usr/local/lib/python3.10/site-packages/sqlalchemy/engine/base.py", line 1710, in _execute_20
    return meth(self, args_10style, kwargs_10style, execution_options)
  File "/usr/local/lib/python3.10/site-packages/sqlalchemy/sql/elements.py", line 334, in _execute_on_connection
    return connection._execute_clauseelement(
  File "/usr/local/lib/python3.10/site-packages/sqlalchemy/engine/base.py", line 1577, in _execute_clauseelement
    ret = self._execute_context(
  File "/usr/local/lib/python3.10/site-packages/sqlalchemy/engine/base.py", line 1953, in _execute_context
    self._handle_dbapi_exception(
  File "/usr/local/lib/python3.10/site-packages/sqlalchemy/engine/base.py", line 2134, in _handle_dbapi_exception
    util.raise_(
  File "/usr/local/lib/python3.10/site-packages/sqlalchemy/util/compat.py", line 211, in raise_
    raise exception
  File "/usr/local/lib/python3.10/site-packages/sqlalchemy/engine/base.py", line 1910, in _execute_context
    self.dialect.do_execute(
  File "/usr/local/lib/python3.10/site-packages/sqlalchemy/engine/default.py", line 736, in do_execute
    cursor.execute(statement, parameters)
sqlalchemy.exc.OperationalError: (sqlite3.OperationalError) no such table: user_attribute
[SQL: SELECT user_attribute.welcome_dashboard_id AS user_attribute_welcome_dashboard_id 
FROM user_attribute 
WHERE user_attribute.user_id = ?]
[parameters: (1,)]
(Background on this error at: https://sqlalche.me/e/14/e3q8)
192.168.1.10 - - [18/Jul/2025:07:30:02 +0000] "GET /superset/welcome/ HTTP/1.1" 500 0 "http://192.168.1.111:8088/superset/welcome/" "Mozilla/5.0 (Windows NT 10.0; Win64; x64) AppleWebKit/537.36 (KHTML, like Gecko) Chrome/138.0.0.0 Safari/537.36"
192.168.1.10 - - [18/Jul/2025:07:30:03 +0000] "GET / HTTP/1.1" 302 223 "http://192.168.1.111:8088/superset/welcome/" "Mozilla/5.0 (Windows NT 10.0; Win64; x64) AppleWebKit/537.36 (KHTML, like Gecko) Chrome/138.0.0.0 Safari/537.36"
2025-07-18 07:30:03,441:WARNING:superset.views.error_handling:Exception
Traceback (most recent call last):
  File "/usr/local/lib/python3.10/site-packages/sqlalchemy/engine/base.py", line 1910, in _execute_context
    self.dialect.do_execute(
  File "/usr/local/lib/python3.10/site-packages/sqlalchemy/engine/default.py", line 736, in do_execute
    cursor.execute(statement, parameters)
sqlite3.OperationalError: no such table: user_attribute

The above exception was the direct cause of the following exception:

Traceback (most recent call last):
  File "/usr/local/lib/python3.10/site-packages/flask/app.py", line 1484, in full_dispatch_request
    rv = self.dispatch_request()
  File "/usr/local/lib/python3.10/site-packages/flask/app.py", line 1469, in dispatch_request
    return self.ensure_sync(self.view_functions[rule.endpoint])(**view_args)
  File "/app/superset/utils/log.py", line 303, in wrapper
    value = f(*args, **kwargs)
  File "/app/superset/views/core.py", line 902, in welcome
    .scalar()
  File "/usr/local/lib/python3.10/site-packages/sqlalchemy/orm/query.py", line 2893, in scalar
    ret = self.one()
  File "/usr/local/lib/python3.10/site-packages/sqlalchemy/orm/query.py", line 2870, in one
    return self._iter().one()
  File "/usr/local/lib/python3.10/site-packages/sqlalchemy/orm/query.py", line 2916, in _iter
    result = self.session.execute(
  File "/usr/local/lib/python3.10/site-packages/sqlalchemy/orm/session.py", line 1717, in execute
    result = conn._execute_20(statement, params or {}, execution_options)
  File "/usr/local/lib/python3.10/site-packages/sqlalchemy/engine/base.py", line 1710, in _execute_20
    return meth(self, args_10style, kwargs_10style, execution_options)
  File "/usr/local/lib/python3.10/site-packages/sqlalchemy/sql/elements.py", line 334, in _execute_on_connection
    return connection._execute_clauseelement(
  File "/usr/local/lib/python3.10/site-packages/sqlalchemy/engine/base.py", line 1577, in _execute_clauseelement
    ret = self._execute_context(
  File "/usr/local/lib/python3.10/site-packages/sqlalchemy/engine/base.py", line 1953, in _execute_context
    self._handle_dbapi_exception(
  File "/usr/local/lib/python3.10/site-packages/sqlalchemy/engine/base.py", line 2134, in _handle_dbapi_exception
    util.raise_(
  File "/usr/local/lib/python3.10/site-packages/sqlalchemy/util/compat.py", line 211, in raise_
    raise exception
  File "/usr/local/lib/python3.10/site-packages/sqlalchemy/engine/base.py", line 1910, in _execute_context
    self.dialect.do_execute(
  File "/usr/local/lib/python3.10/site-packages/sqlalchemy/engine/default.py", line 736, in do_execute
    cursor.execute(statement, parameters)
sqlalchemy.exc.OperationalError: (sqlite3.OperationalError) no such table: user_attribute
[SQL: SELECT user_attribute.welcome_dashboard_id AS user_attribute_welcome_dashboard_id 
FROM user_attribute 
WHERE user_attribute.user_id = ?]
[parameters: (1,)]
(Background on this error at: https://sqlalche.me/e/14/e3q8)
2025-07-18 07:30:03,442:ERROR:superset.views.error_handling:(sqlite3.OperationalError) no such table: user_attribute
[SQL: SELECT user_attribute.welcome_dashboard_id AS user_attribute_welcome_dashboard_id 
FROM user_attribute 
WHERE user_attribute.user_id = ?]
[parameters: (1,)]
(Background on this error at: https://sqlalche.me/e/14/e3q8)
Traceback (most recent call last):
  File "/usr/local/lib/python3.10/site-packages/sqlalchemy/engine/base.py", line 1910, in _execute_context
    self.dialect.do_execute(
  File "/usr/local/lib/python3.10/site-packages/sqlalchemy/engine/default.py", line 736, in do_execute
    cursor.execute(statement, parameters)
sqlite3.OperationalError: no such table: user_attribute

The above exception was the direct cause of the following exception:

Traceback (most recent call last):
  File "/usr/local/lib/python3.10/site-packages/flask/app.py", line 1484, in full_dispatch_request
    rv = self.dispatch_request()
  File "/usr/local/lib/python3.10/site-packages/flask/app.py", line 1469, in dispatch_request
    return self.ensure_sync(self.view_functions[rule.endpoint])(**view_args)
  File "/app/superset/utils/log.py", line 303, in wrapper
    value = f(*args, **kwargs)
  File "/app/superset/views/core.py", line 902, in welcome
    .scalar()
  File "/usr/local/lib/python3.10/site-packages/sqlalchemy/orm/query.py", line 2893, in scalar
    ret = self.one()
  File "/usr/local/lib/python3.10/site-packages/sqlalchemy/orm/query.py", line 2870, in one
    return self._iter().one()
  File "/usr/local/lib/python3.10/site-packages/sqlalchemy/orm/query.py", line 2916, in _iter
    result = self.session.execute(
  File "/usr/local/lib/python3.10/site-packages/sqlalchemy/orm/session.py", line 1717, in execute
    result = conn._execute_20(statement, params or {}, execution_options)
  File "/usr/local/lib/python3.10/site-packages/sqlalchemy/engine/base.py", line 1710, in _execute_20
    return meth(self, args_10style, kwargs_10style, execution_options)
  File "/usr/local/lib/python3.10/site-packages/sqlalchemy/sql/elements.py", line 334, in _execute_on_connection
    return connection._execute_clauseelement(
  File "/usr/local/lib/python3.10/site-packages/sqlalchemy/engine/base.py", line 1577, in _execute_clauseelement
    ret = self._execute_context(
  File "/usr/local/lib/python3.10/site-packages/sqlalchemy/engine/base.py", line 1953, in _execute_context
    self._handle_dbapi_exception(
  File "/usr/local/lib/python3.10/site-packages/sqlalchemy/engine/base.py", line 2134, in _handle_dbapi_exception
    util.raise_(
  File "/usr/local/lib/python3.10/site-packages/sqlalchemy/util/compat.py", line 211, in raise_
    raise exception
  File "/usr/local/lib/python3.10/site-packages/sqlalchemy/engine/base.py", line 1910, in _execute_context
    self.dialect.do_execute(
  File "/usr/local/lib/python3.10/site-packages/sqlalchemy/engine/default.py", line 736, in do_execute
    cursor.execute(statement, parameters)
sqlalchemy.exc.OperationalError: (sqlite3.OperationalError) no such table: user_attribute
[SQL: SELECT user_attribute.welcome_dashboard_id AS user_attribute_welcome_dashboard_id 
FROM user_attribute 
WHERE user_attribute.user_id = ?]
[parameters: (1,)]
(Background on this error at: https://sqlalche.me/e/14/e3q8)
192.168.1.10 - - [18/Jul/2025:07:30:03 +0000] "GET /superset/welcome/ HTTP/1.1" 500 0 "http://192.168.1.111:8088/superset/welcome/" "Mozilla/5.0 (Windows NT 10.0; Win64; x64) AppleWebKit/537.36 (KHTML, like Gecko) Chrome/138.0.0.0 Safari/537.36"